<mujoco model="scene">
  <compiler angle="radian"/>

  <option gravity="0 0 0"/>

  <default>
    <joint limited="true" damping="1"/>
    <geom friction="1 0.02 0.01"/>
    <general biastype="affine" gainprm="50" biasprm="0 -50"/>
  </default>

  <worldbody>
    <geom name="ground" size="3 3 0.1" type="plane"/>
    <camera name="overview" pos="0 -1 0.6" quat="0.850651 0.525731 0 0"/>
    <light pos="0 0 2" dir="0 0 -1"/>
    <body name="body" pos="0 0 0.3">
      <joint type="free" damping="0"/>
      <geom size="0.1 0.06 0.02" type="box" rgba="0.6 0.6 0.6 1"/>
      <body name="LF" pos="0.08 0.05 0">
        <joint name="LF_coxa" pos="0 0 0" axis="0 0 1" range="0 3.14159"/>
        <geom size="0.008 0.02" pos="0.02 0 0" quat="0.707107 0 -0.707107 0" type="capsule"/>
        <body pos="0.04 0 0">
          <joint name="LF_femur" pos="0 0 0" axis="0 1 0" range="-1.0472 1.0472"/>
          <geom size="0.007 0.04" pos="0.04 0 0" quat="0.707107 0 -0.707107 0" type="capsule"/>
          <body pos="0.08 0 0">
            <joint name="LF_tibia" pos="0 0 0" axis="0 1 0" range="-0.174533 1.74533"/>
            <geom size="0.006 0.05" pos="0.05 0 0" quat="0.707107 0 -0.707107 0" type="capsule"/>
          </body>
        </body>
      </body>
      <body name="RF" pos="0.08 -0.05 0" quat="0 0 0 1">
        <joint name="RF_coxa" pos="0 0 0" axis="0 0 1" range="0 3.14159"/>
        <geom size="0.008 0.02" pos="0.02 0 0" quat="0.707107 0 -0.707107 0" type="capsule"/>
        <body pos="0.04 0 0">
          <joint name="RF_femur" pos="0 0 0" axis="0 1 0" range="-1.0472 1.0472"/>
          <geom size="0.007 0.04" pos="0.04 0 0" quat="0.707107 0 -0.707107 0" type="capsule"/>
          <body pos="0.08 0 0">
            <joint name="RF_tibia" pos="0 0 0" axis="0 1 0" range="-0.174533 1.74533"/>
            <geom size="0.006 0.05" pos="0.05 0 0" quat="0.707107 0 -0.707107 0" type="capsule"/>
          </body>
        </body>
      </body>
      <body name="LM" pos="0 0.05 0">
        <joint name="LM_coxa" pos="0 0 0" axis="0 0 1" range="0 3.14159"/>
        <geom size="0.008 0.02" pos="0.02 0 0" quat="0.707107 0 -0.707107 0" type="capsule"/>
        <body pos="0.04 0 0">
          <joint name="LM_femur" pos="0 0 0" axis="0 1 0" range="-1.0472 1.0472"/>
          <geom size="0.007 0.04" pos="0.04 0 0" quat="0.707107 0 -0.707107 0" type="capsule"/>
          <body pos="0.08 0 0">
            <joint name="LM_tibia" pos="0 0 0" axis="0 1 0" range="-0.174533 1.74533"/>
            <geom size="0.006 0.05" pos="0.05 0 0" quat="0.707107 0 -0.707107 0" type="capsule"/>
          </body>
        </body>
      </body>
      <body name="RM" pos="0 -0.05 0" quat="0 0 0 1">
        <joint name="RM_coxa" pos="0 0 0" axis="0 0 1" range="0 3.14159"/>
        <geom size="0.008 0.02" pos="0.02 0 0" quat="0.707107 0 -0.707107 0" type="capsule"/>
        <body pos="0.04 0 0">
          <joint name="RM_femur" pos="0 0 0" axis="0 1 0" range="-1.0472 1.0472"/>
          <geom size="0.007 0.04" pos="0.04 0 0" quat="0.707107 0 -0.707107 0" type="capsule"/>
          <body pos="0.08 0 0">
            <joint name="RM_tibia" pos="0 0 0" axis="0 1 0" range="-0.174533 1.74533"/>
            <geom size="0.006 0.05" pos="0.05 0 0" quat="0.707107 0 -0.707107 0" type="capsule"/>
          </body>
        </body>
      </body>
      <body name="LR" pos="-0.08 0.05 0">
        <joint name="LR_coxa" pos="0 0 0" axis="0 0 1" range="0 3.14159"/>
        <geom size="0.008 0.02" pos="0.02 0 0" quat="0.707107 0 -0.707107 0" type="capsule"/>
        <body pos="0.04 0 0">
          <joint name="LR_femur" pos="0 0 0" axis="0 1 0" range="-1.0472 1.0472"/>
          <geom size="0.007 0.04" pos="0.04 0 0" quat="0.707107 0 -0.707107 0" type="capsule"/>
          <body pos="0.08 0 0">
            <joint name="LR_tibia" pos="0 0 0" axis="0 1 0" range="-0.174533 1.74533"/>
            <geom size="0.006 0.05" pos="0.05 0 0" quat="0.707107 0 -0.707107 0" type="capsule"/>
          </body>
        </body>
      </body>
      <body name="RR" pos="-0.08 -0.05 0" quat="0 0 0 1">
        <joint name="RR_coxa" pos="0 0 0" axis="0 0 1" range="0 3.14159"/>
        <geom size="0.008 0.02" pos="0.02 0 0" quat="0.707107 0 -0.707107 0" type="capsule"/>
        <body pos="0.04 0 0">
          <joint name="RR_femur" pos="0 0 0" axis="0 1 0" range="-1.0472 1.0472"/>
          <geom size="0.007 0.04" pos="0.04 0 0" quat="0.707107 0 -0.707107 0" type="capsule"/>
          <body pos="0.08 0 0">
            <joint name="RR_tibia" pos="0 0 0" axis="0 1 0" range="-0.174533 1.74533"/>
            <geom size="0.006 0.05" pos="0.05 0 0" quat="0.707107 0 -0.707107 0" type="capsule"/>
          </body>
        </body>
      </body>
    </body>
  </worldbody>

  <actuator>
    <general joint="LF_coxa"/>
    <general joint="LF_femur"/>
    <general joint="LF_tibia"/>
    <general joint="RF_coxa"/>
    <general joint="RF_femur"/>
    <general joint="RF_tibia"/>
    <general joint="LM_coxa"/>
    <general joint="LM_femur"/>
    <general joint="LM_tibia"/>
    <general joint="RM_coxa"/>
    <general joint="RM_femur"/>
    <general joint="RM_tibia"/>
    <general joint="LR_coxa"/>
    <general joint="LR_femur"/>
    <general joint="LR_tibia"/>
    <general joint="RR_coxa"/>
    <general joint="RR_femur"/>
    <general joint="RR_tibia"/>
  </actuator>
</mujoco>
